Workbook
Name Slicer_CATEGORY_OF_PRODUCT: #N/A

Sheet inventory_data
A1: UNIQUE_ID_OF_PRODUCT | B1: CATEGORY_OF_PRODUCT | C1: PRODUCT_NAME | D1: NO_OF_STOCK_UNIT_PURCHASED_BY_STORE | E1: NO_OF_STOCK_LEFT | F1: UNIT_COST_FROM_COMPANY_TO_STORE | G1: MRP | H1: DISCOUNT_GIVEN_BY_COMPANY_TO_STORE | I1: ACTUAL_PRICE_TO_CUSTOMER | J1: EXPIRY_DATE_OF_PRODUCT | K1: DATE_OF_STOCK_PURCHASED | L1: PURCHASED_COMPANY_NAME | M1: COMPANY_EMAIL_FOR_ORDERING | N1: DISCOUNT | O1: PRICE_AFTER_DISCOUNT | P1: SOLD_STOCK | Q1: PROFIT | R1: DAYS LEFT | S1: EXPIRY STATUS
A2: P001 | B2: Personal Care | C2: Dettol Handwash 200ml | D2: 50 | E2: 10 | F2: 86.49 | G2: 128.67 | H2: 9.34 | I2: 127.25 | J2: 46044 | K2: 45859 | L2: Detol | M2: 23p314403@acet.ac.in | N2: =IF(OR(E2>200,J2<=TODAY()+30),0.4, IF(OR(AND(E2>=100,E2<=200),J2<=TODAY()+90),0.2,0.05)) -> 0.2 | O2: =G2*(1-N2) -> 102.936 | P2: =(inventory_data!$D2-inventory_data!$E2) -> 40 | Q2: =(G2-F2)*P2 -> 1687.2 | R2: =J2-TODAY() -> 77 | S2: =IF(R2<=40,"Near Expiry",IF(R2>41,"Far Expiry")) -> Far Expiry
A3: P002 | B3: Bakery | C3: Parle G 100g | D3: 355 | E3: 219 | F3: 26.45 | G3: 34.84 | H3: 7.24 | I3: 32.38 | J3: 46590 | K3: 45860 | L3: Britannia | M3: 23p31a4442@acet.ac.in | N3: =IF(OR(E3>200,J3<=TODAY()+30),0.4, IF(OR(AND(E3>=100,E3<=200),J3<=TODAY()+90),0.2,0.05)) -> 0.4 | O3: =G3*(1-N3) -> 20.904 | P3: =(inventory_data!$D3-inventory_data!$E3) -> 136 | Q3: =(G3-F3)*P3 -> 1141.04 | R3: =J3-TODAY() -> 623 | S3: =IF(R3<=40,"Near Expiry",IF(R3>41,"Far Expiry")) -> Far Expiry
A4: P003 | B4: Snacks | C4: Lays Classic 50g | D4: 479 | E4: 97 | F4: 120.29 | G4: 161.5 | H4: 3.86 | I4: 160.51 | J4: 45910 | K4: 45848 | L4: ITC | M4: 23p31a4442@acet.ac.in | N4: =IF(OR(E4>200,J4<=TODAY()+30),0.4, IF(OR(AND(E4>=100,E4<=200),J4<=TODAY()+90),0.2,0.05)) -> 0.4 | O4: =G4*(1-N4) -> 96.9 | P4: =(inventory_data!$D4-inventory_data!$E4) -> 382 | Q4: =(G4-F4)*P4 -> 15742.22 | R4: =J4-TODAY() -> -57 | S4: =IF(R4<=40,"Near Expiry",IF(R4>41,"Far Expiry")) -> Near Expiry
A5: P004 | B5: Personal Care | C5: Dove Soap 75g | D5: 139 | E5: 3 | F5: 199.19 | G5: 289.98 | H5: 7 | I5: 283.45 | J5: 46723 | K5: 45758 | L5: Hindustan Unilever | M5: 23p31a4403@acet.ac.in | N5: =IF(OR(E5>200,J5<=TODAY()+30),0.4, IF(OR(AND(E5>=100,E5<=200),J5<=TODAY()+90),0.2,0.05)) -> 0.05 | O5: =G5*(1-N5) -> 275.481 | P5: =(inventory_data!$D5-inventory_data!$E5) -> 136 | Q5: =(G5-F5)*P5 -> 12347.44 | R5: =J5-TODAY() -> 756 | S5: =IF(R5<=40,"Near Expiry",IF(R5>41,"Far Expiry")) -> Far Expiry
A6: P005 | B6: Grocery | C6: Maggie Noodles 70g | D6: 184 | E6: 96 | F6: 57.15 | G6: 81.26 | H6: 7.22 | I6: 81.03 | J6: 46479 | K6: 45857 | L6: Nestle | M6: 23p31a4442@acet.ac.in | N6: =IF(OR(E6>200,J6<=TODAY()+30),0.4, IF(OR(AND(E6>=100,E6<=200),J6<=TODAY()+90),0.2,0.05)) -> 0.05 | O6: =G6*(1-N6) -> 77.197 | P6: =(inventory_data!$D6-inventory_data!$E6) -> 88 | Q6: =(G6-F6)*P6 -> 2121.68 | R6: =J6-TODAY() -> 512 | S6: =IF(R6<=40,"Near Expiry",IF(R6>41,"Far Expiry")) -> Far Expiry
A7: P006 | B7: Personal Care | C7: Dove Soap 75g | D7: 93 | E7: 75 | F7: 128.76 | G7: 165.26 | H7: 9.07 | I7: 159.36 | J7: 46003 | K7: 45803 | L7: Hindustan Unilever | M7: 23p31a4403@acet.ac.in | N7: =IF(OR(E7>200,J7<=TODAY()+30),0.4, IF(OR(AND(E7>=100,E7<=200),J7<=TODAY()+90),0.2,0.05)) -> 0.2 | O7: =G7*(1-N7) -> 132.208 | P7: =(inventory_data!$D7-inventory_data!$E7) -> 18 | Q7: =(G7-F7)*P7 -> 657 | R7: =J7-TODAY() -> 36 | S7: =IF(R7<=40,"Near Expiry",IF(R7>41,"Far Expiry")) -> Near Expiry
A8: P007 | B8: Dairy | C8: Amul Butter | D8: 222 | E8: 73 | F8: 82.46 | G8: 117.51 | H8: 2.95 | I8: 117.51 | J8: 46024 | K8: 45852 | L8: Amul | M8: 23p31a4403@acet.ac.in | N8: =IF(OR(E8>200,J8<=TODAY()+30),0.4, IF(OR(AND(E8>=100,E8<=200),J8<=TODAY()+90),0.2,0.05)) -> 0.2 | O8: =G8*(1-N8) -> 94.008 | P8: =(inventory_data!$D8-inventory_data!$E8) -> 149 | Q8: =(G8-F8)*P8 -> 5222.45 | R8: =J8-TODAY() -> 57 | S8: =IF(R8<=40,"Near Expiry",IF(R8>41,"Far Expiry")) -> Far Expiry
A9: P008 | B9: Bakery | C9: Sunfeast Biscuits 200g | D9: 154 | E9: 122 | F9: 24.5 | G9: 30.68 | H9: 4.6 | I9: 28.42 | J9: 46104 | K9: 45759 | L9: ITC | M9: 23p31a4442@acet.ac.in | N9: =IF(OR(E9>200,J9<=TODAY()+30),0.4, IF(OR(AND(E9>=100,E9<=200),J9<=TODAY()+90),0.2,0.05)) -> 0.2 | O9: =G9*(1-N9) -> 24.544 | P9: =(inventory_data!$D9-inventory_data!$E9) -> 32 | Q9: =(G9-F9)*P9 -> 197.76 | R9: =J9-TODAY() -> 137 | S9: =IF(R9<=40,"Near Expiry",IF(R9>41,"Far Expiry")) -> Far Expiry
A10: P009 | B10: Household | C10: Godrej Air Freshener | D10: 222 | E10: 132 | F10: 152.98 | G10: 205.29 | H10: 6.22 | I10: 202.74 | J10: 46679 | K10: 45777 | L10: Godrej | M10: 23p31a4442@acet.ac.in | N10: =IF(OR(E10>200,J10<=TODAY()+30),0.4, IF(OR(AND(E10>=100,E10<=200),J10<=TODAY()+90),0.2,0.05)) -> 0.2 | O10: =G10*(1-N10) -> 164.232 | P10: =(inventory_data!$D10-inventory_data!$E10) -> 90 | Q10: =(G10-F10)*P10 -> 4707.9 | R10: =J10-TODAY() -> 712 | S10: =IF(R10<=40,"Near Expiry",IF(R10>41,"Far Expiry")) -> Far Expiry
A11: P010 | B11: Grocery | C11: Fortune Oil 1L | D11: 450 | E11: 331 | F11: 70.4 | G11: 100.06 | H11: 4.42 | I11: 97.87 | J11: 46686 | K11: 45803 | L11: ITC | M11: 23p31a4442@acet.ac.in | N11: =IF(OR(E11>200,J11<=TODAY()+30),0.4, IF(OR(AND(E11>=100,E11<=200),J11<=TODAY()+90),0.2,0.05)) -> 0.4 | O11: =G11*(1-N11) -> 60.036 | P11: =(inventory_data!$D11-inventory_data!$E11) -> 119 | Q11: =(G11-F11)*P11 -> 3529.54 | R11: =J11-TODAY() -> 719 | S11: =IF(R11<=40,"Near Expiry",IF(R11>41,"Far Expiry")) -> Far Expiry
A12: P011 | B12: Beverages | C12: Coca Cola 1L | D12: 357 | E12: 97 | F12: 58.98 | G12: 86.99 | H12: 8.12 | I12: 81.19 | J12: 45929 | K12: 45838 | L12: Coca Cola India | M12: 23p31a4442@acet.ac.in | N12: =IF(OR(E12>200,J12<=TODAY()+30),0.4, IF(OR(AND(E12>=100,E12<=200),J12<=TODAY()+90),0.2,0.05)) -> 0.4 | O12: =G12*(1-N12) -> 52.194 | P12: =(inventory_data!$D12-inventory_data!$E12) -> 260 | Q12: =(G12-F12)*P12 -> 7282.6 | R12: =J12-TODAY() -> -38 | S12: =IF(R12<=40,"Near Expiry",IF(R12>41,"Far Expiry")) -> Near Expiry
A13: P012 | B13: Dairy | C13: Mother Dairy Toned Milk Pouch | D13: 50 | E13: 3 | F13: 39.79 | G13: 47.96 | H13: 3.94 | I13: 47.4 | J13: 45899 | K13: 45783 | L13: Amul | M13: 23p31a4403@acet.ac.in | N13: =IF(OR(E13>200,J13<=TODAY()+30),0.4, IF(OR(AND(E13>=100,E13<=200),J13<=TODAY()+90),0.2,0.05)) -> 0.4 | O13: =G13*(1-N13) -> 28.776 | P13: =(inventory_data!$D13-inventory_data!$E13) -> 47 | Q13: =(G13-F13)*P13 -> 383.99 | R13: =J13-TODAY() -> -68 | S13: =IF(R13<=40,"Near Expiry",IF(R13>41,"Far Expiry")) -> Near Expiry
... A200: P200 | B200: Dairy | C200: Nestle A+ Nourish Dahi | D200: 121 | E200: 10 | F200: 148.75 | G200: 217.5 | H200: 2.85 | I200: 215.52 | J200: 45930 | K200: 45812 | L200: Amul | M200: 23p31a4403@acet.ac.in | N200: =IF(OR(E200>200,J200<=TODAY()+30),0.4, IF(OR(AND(E200>=100,E200<=200),J200<=TODAY()+90),0.2,0.05)) -> 0.4 | O200: =G200*(1-N200) -> 130.5 | P200: =(inventory_data!$D200-inventory_data!$E200) -> 111 | Q200: =(G200-F200)*P200 -> 7631.25 | R200: =J200-TODAY() -> -37 | S200: =IF(R200<=40,"Near Expiry",IF(R200>41,"Far Expiry")) -> Near Expiry

Sheet pivot
B5: Sum of NO_OF_STOCK_LEFT | C5: Sum of NO_OF_STOCK_UNIT_PURCHASED_BY_STORE | D5: Sum of SOLD_STOCK | F5: {=C5:D6} -> Sum of NO_OF_STOCK_UNIT_PURCHASED_BY_STORE | G5: Sum of SOLD_STOCK | I5: {=B5:C6} -> Sum of NO_OF_STOCK_LEFT | J5: Sum of NO_OF_STOCK_UNIT_PURCHASED_BY_STORE
B6: 26218 | C6: 54727 | D6: 28509 | F6: 54727 | G6: 28509 | I6: 26218 | J6: 54727
B11: Row Labels | C11: Sum of PROFIT
B12: Bakery | C12: 311122.98 | F12: Row Labels | G12: Average of DISCOUNT
B13: Beverages | C13: 193209.26 | F13: Amul Butter - Pasteurised | G13: 0.4
B14: Dairy | C14: 194157.64 | F14: Britannia Bread 400g | G14: 0.05
B15: Frozen Foods | C15: 143168.84 | F15: Britannia Butter 500g – Britannia Industries | G15: 0.4
B16: Grocery | C16: 227825.31 | F16: Coca Cola 1L | G16: 0.05
B17: Household | C17: 329570.18 | F17: Colgate Toothpaste 100g | G17: 0.225
B18: Personal Care | C18: 426026.63 | F18: Dove Soap 75g | G18: 0.2
B19: Snacks | C19: 134487.56 | F19: Fortune Oil 1L | G19: 0.3
B20: Grand Total | C20: 1959568.4 | F20: Godrej Air Freshener | G20: 0.14
F21: Kwality Walls Ice Cream 500ml | G21: 0.26666667 | J21: Row Labels | K21: Sum of NO_OF_STOCK_LEFT | N21: {=J21:K29} -> Row Labels | O21: Sum of NO_OF_STOCK_LEFT
B22: {=B11:C19} -> Row Labels | C22: Sum of PROFIT | F22: Maggie Noodles 70g | G22: 0.125 | J22: Bakery | K22: 3407 | N22: Bakery | O22: 3407
B23: Bakery | C23: 311122.98 | F23: Nestle Milk 1L | G23: 0.05 | J23: Beverages | K23: 2664 | N23: Beverages | O23: 2664
B24: Beverages | C24: 193209.26 | F24: Patanjali Cow Ghee 500ml | G24: 0.4 | J24: Dairy | K24: 2264 | N24: Dairy | O24: 2264
B25: Dairy | C25: 194157.64 | F25: Pepsi 500ml | G25: 0.225 | J25: Frozen Foods | K25: 2586 | N25: Frozen Foods | O25: 2586
B26: Frozen Foods | C26: 143168.84 | F26: Tide Detergent 1kg | G26: 0.0875 | J26: Grocery | K26: 4241 | N26: Grocery | O26: 4241
B27: Grocery | C27: 227825.31 | F27: Grand Total | G27: 0.19074074 | J27: Household | K27: 4659 | N27: Household | O27: 4659
B28: Household | C28: 329570.18 | J28: Personal Care | K28: 5137 | N28: Personal Care | O28: 5137
B29: Personal Care | C29: 426026.63 | G29: Average of DISCOUNT | J29: Snacks | K29: 1260 | N29: Snacks | O29: 1260
B30: Snacks | C30: 134487.56 | G30: 0.18869347 | J30: Grand Total | K30: 26218
Q32: EXPIRY STATUS | R32: Near Expiry
J33: Row Labels | K33: Sum of SOLD_STOCK | N33: {=J33:K41} -> Row Labels | O33: Sum of SOLD_STOCK
J34: Bakery | K34: 4931 | N34: Bakery | O34: 4931 | Q34: Row Labels | R34: Count of EXPIRY STATUS | T34: {=Q34:R48} -> Row Labels | U34: Count of EXPIRY STATUS
J35: Beverages | K35: 2550 | N35: Beverages | O35: 2550 | Q35: Amul Butter - Pasteurised | R35: 1 | T35: Amul Butter - Pasteurised | U35: 1
B36: Count of PRODUCT_NAME | J36: Dairy | K36: 3403 | N36: Dairy | O36: 3403 | Q36: Britannia Bread 400g | R36: 2 | T36: Britannia Bread 400g | U36: 2
B37: 199 | J37: Frozen Foods | K37: 2613 | N37: Frozen Foods | O37: 2613 | Q37: Britannia Pav | R37: 1 | T37: Britannia Pav | U37: 1
J38: Grocery | K38: 4020 | N38: Grocery | O38: 4020 | Q38: Colgate Toothpaste 100g | R38: 2 | T38: Colgate Toothpaste 100g | U38: 2
J39: Household | K39: 3937 | N39: Household | O39: 3937 | Q39: Dove Soap 75g | R39: 1 | T39: Dove Soap 75g | U39: 1
J40: Personal Care | K40: 5757 | N40: Personal Care | O40: 5757 | Q40: Fortune Oil 1L | R40: 2 | T40: Fortune Oil 1L | U40: 2
J41: Snacks | K41: 1298 | N41: Snacks | O41: 1298 | Q41: Kwality Walls Ice Cream 500ml | R41: 1 | T41: Kwality Walls Ice Cream 500ml | U41: 1
B42: EXPIRY STATUS | C42: Near Expiry | J42: Grand Total | K42: 28509 | Q42: Maggie Noodles 70g | R42: 1 | T42: Maggie Noodles 70g | U42: 1
Q43: Mother Dairy Toned Milk Pouch | R43: 1 | T43: Mother Dairy Toned Milk Pouch | U43: 1
B44: Count of EXPIRY STATUS | Q44: Nestle Milk 1L | R44: 5 | T44: Nestle Milk 1L | U44: 5
B45: 26 | Q45: Parle G 100g | R45: 2 | T45: Parle G 100g | U45: 2
Q46: Pepsi 500ml | R46: 4 | T46: Pepsi 500ml | U46: 4
Q47: Sunfeast Biscuits 200g | R47: 1 | T47: Sunfeast Biscuits 200g | U47: 1
J48: CATEGORY_OF_PRODUCT | K48: Bakery | Q48: Tide Detergent 1kg | R48: 1 | T48: Tide Detergent 1kg | U48: 1
B49: Sum of DISCOUNT | C49: Sum of NO_OF_STOCK_LEFT | Q49: Pepsi 1L | R49: 1
...

Sheet DASHBOARD
W4: Product | X4: Average of DISCOUNT
W5: Britannia Bread 400g | X5: 0.145
W6: Heritage Salted Butter 500g – Heritage Foods | X6: 0.05
W7: Parle G 100g | X7: 0.20714286
W8: Patanjali Cow Ghee 500ml | X8: 0.4
W9: Sunfeast Biscuits 200g | X9: 0.18
W10: Grand Total | X10: 0.18387097
